[2025-07-11 22:25:45 +0000] [9634] [INFO] Starting gunicorn 23.0.0
[2025-07-11 22:25:45 +0000] [9634] [ERROR] Connection in use: ('::', 8793)
[2025-07-11 22:25:45 +0000] [9634] [ERROR] connection to ('::', 8793) failed: [Errno 98] Address already in use
[2025-07-11 22:25:46 +0000] [9634] [ERROR] Connection in use: ('::', 8793)
[2025-07-11 22:25:46 +0000] [9634] [ERROR] connection to ('::', 8793) failed: [Errno 98] Address already in use
[2025-07-11 22:25:47 +0000] [9634] [ERROR] Connection in use: ('::', 8793)
[2025-07-11 22:25:47 +0000] [9634] [ERROR] connection to ('::', 8793) failed: [Errno 98] Address already in use
[2025-07-11 22:25:48 +0000] [9634] [ERROR] Connection in use: ('::', 8793)
[2025-07-11 22:25:48 +0000] [9634] [ERROR] connection to ('::', 8793) failed: [Errno 98] Address already in use
[2025-07-11 22:25:49 +0000] [9634] [ERROR] Connection in use: ('::', 8793)
[2025-07-11 22:25:49 +0000] [9634] [ERROR] connection to ('::', 8793) failed: [Errno 98] Address already in use
[2025-07-11 22:25:50 +0000] [9634] [ERROR] Can't connect to ('::', 8793)
/home/ubuntu/airflow_venv/lib/python3.12/site-packages/airflow/sdk/execution_time/supervisor.py:460 DeprecationWarning: This process (pid=56660) is multi-threaded, use of fork() may lead to deadlocks in the child.
Traceback (most recent call last):
  File "/home/ubuntu/airflow_venv/bin/airflow", line 8, in <module>
    sys.exit(main())
             ^^^^^^
  File "/home/ubuntu/airflow_venv/lib/python3.12/site-packages/airflow/__main__.py", line 55, in main
    args.func(args)
  File "/home/ubuntu/airflow_venv/lib/python3.12/site-packages/airflow/cli/cli_config.py", line 48, in command
    return func(*args, **kwargs)
           ^^^^^^^^^^^^^^^^^^^^^
  File "/home/ubuntu/airflow_venv/lib/python3.12/site-packages/airflow/utils/cli.py", line 112, in wrapper
    return f(*args, **kwargs)
           ^^^^^^^^^^^^^^^^^^
  File "/home/ubuntu/airflow_venv/lib/python3.12/site-packages/airflow/utils/providers_configuration_loader.py", line 55, in wrapped_function
    return func(*args, **kwargs)
           ^^^^^^^^^^^^^^^^^^^^^
  File "/home/ubuntu/airflow_venv/lib/python3.12/site-packages/airflow/cli/commands/scheduler_command.py", line 52, in scheduler
    run_command_with_daemon_option(
  File "/home/ubuntu/airflow_venv/lib/python3.12/site-packages/airflow/cli/commands/daemon_utils.py", line 81, in run_command_with_daemon_option
    callback()
  File "/home/ubuntu/airflow_venv/lib/python3.12/site-packages/airflow/cli/commands/scheduler_command.py", line 55, in <lambda>
    callback=lambda: _run_scheduler_job(args),
                     ^^^^^^^^^^^^^^^^^^^^^^^^
  File "/home/ubuntu/airflow_venv/lib/python3.12/site-packages/airflow/cli/commands/scheduler_command.py", line 43, in _run_scheduler_job
    run_job(job=job_runner.job, execute_callable=job_runner._execute)
  File "/home/ubuntu/airflow_venv/lib/python3.12/site-packages/airflow/utils/session.py", line 101, in wrapper
    return func(*args, session=session, **kwargs)
           ^^^^^^^^^^^^^^^^^^^^^^^^^^^^^^^^^^^^^^
  File "/home/ubuntu/airflow_venv/lib/python3.12/site-packages/airflow/jobs/job.py", line 347, in run_job
    return execute_job(job, execute_callable=execute_callable)
           ^^^^^^^^^^^^^^^^^^^^^^^^^^^^^^^^^^^^^^^^^^^^^^^^^^^
  File "/home/ubuntu/airflow_venv/lib/python3.12/site-packages/airflow/jobs/job.py", line 376, in execute_job
    ret = execute_callable()
          ^^^^^^^^^^^^^^^^^^
  File "/home/ubuntu/airflow_venv/lib/python3.12/site-packages/airflow/jobs/scheduler_job_runner.py", line 1015, in _execute
    self._run_scheduler_loop()
  File "/home/ubuntu/airflow_venv/lib/python3.12/site-packages/airflow/jobs/scheduler_job_runner.py", line 1296, in _run_scheduler_loop
    num_queued_tis = self._do_scheduling(session)
                     ^^^^^^^^^^^^^^^^^^^^^^^^^^^^
  File "/home/ubuntu/airflow_venv/lib/python3.12/site-packages/airflow/jobs/scheduler_job_runner.py", line 1387, in _do_scheduling
    self._create_dagruns_for_dags(guard, session)
  File "/home/ubuntu/airflow_venv/lib/python3.12/site-packages/airflow/utils/retries.py", line 93, in wrapped_function
    for attempt in run_with_db_retries(max_retries=retries, logger=logger, **retry_kwargs):
  File "/home/ubuntu/airflow_venv/lib/python3.12/site-packages/tenacity/__init__.py", line 445, in __iter__
    do = self.iter(retry_state=retry_state)
         ^^^^^^^^^^^^^^^^^^^^^^^^^^^^^^^^^^
  File "/home/ubuntu/airflow_venv/lib/python3.12/site-packages/tenacity/__init__.py", line 378, in iter
    result = action(retry_state)
             ^^^^^^^^^^^^^^^^^^^
  File "/home/ubuntu/airflow_venv/lib/python3.12/site-packages/tenacity/__init__.py", line 400, in <lambda>
    self._add_action_func(lambda rs: rs.outcome.result())
                                     ^^^^^^^^^^^^^^^^^^^
  File "/usr/lib/python3.12/concurrent/futures/_base.py", line 449, in result
    return self.__get_result()
           ^^^^^^^^^^^^^^^^^^^
  File "/usr/lib/python3.12/concurrent/futures/_base.py", line 401, in __get_result
    raise self._exception
  File "/home/ubuntu/airflow_venv/lib/python3.12/site-packages/airflow/utils/retries.py", line 102, in wrapped_function
    return func(*args, **kwargs)
           ^^^^^^^^^^^^^^^^^^^^^
  File "/home/ubuntu/airflow_venv/lib/python3.12/site-packages/airflow/jobs/scheduler_job_runner.py", line 1465, in _create_dagruns_for_dags
    guard.commit()
  File "/home/ubuntu/airflow_venv/lib/python3.12/site-packages/airflow/utils/sqlalchemy.py", line 399, in commit
    self.session.commit()
  File "/home/ubuntu/airflow_venv/lib/python3.12/site-packages/sqlalchemy/orm/session.py", line 1454, in commit
    self._transaction.commit(_to_root=self.future)
  File "/home/ubuntu/airflow_venv/lib/python3.12/site-packages/sqlalchemy/orm/session.py", line 830, in commit
    self._assert_active(prepared_ok=True)
  File "/home/ubuntu/airflow_venv/lib/python3.12/site-packages/sqlalchemy/orm/session.py", line 604, in _assert_active
    raise sa_exc.PendingRollbackError(
sqlalchemy.exc.PendingRollbackError: This Session's transaction has been rolled back due to a previous exception during flush. To begin a new transaction with this Session, first issue Session.rollback(). Original exception was: (sqlite3.IntegrityError) UNIQUE constraint failed: dag_run.dag_id, dag_run.logical_date
[SQL: INSERT INTO dag_run (dag_id, queued_at, logical_date, start_date, end_date, state, run_id, creating_job_id, run_type, triggered_by, conf, data_interval_start, data_interval_end, run_after, last_scheduling_decision, log_template_id, updated_at, clear_number, backfill_id, bundle_version, scheduled_by_job_id, context_carrier, created_dag_version_id) VALUES (?, ?, ?, ?, ?, ?, ?, ?, ?, ?, ?, ?, ?, ?, ?, ?, ?, ?, ?, ?, ?, ?, ?)]
[parameters: ('weathermap_api', '2025-07-12 00:00:02.094302', '2025-07-12 00:00:00.000000', None, None, <DagRunState.QUEUED: 'queued'>, 'scheduled__2025-07-12T00:00:00+00:00', 15, <DagRunType.SCHEDULED: 'scheduled'>, 'TIMETABLE', '{}', '2025-07-12 00:00:00.000000', '2025-07-12 00:00:00.000000', '2025-07-12 00:00:00.000000', None, 1, '2025-07-12 00:00:02.108984', 0, None, None, None, '{"__var": {}, "__type": "dict"}', '0197fbdb3b547f6db1b60019083b933f')]
(Background on this error at: https://sqlalche.me/e/14/gkpj) (Background on this error at: https://sqlalche.me/e/14/7s2a)
